<<<<<<< HEAD
----------------------------------------------------------------
Thu Nov 07 16:35:30 CET 2024:
Booting Derby version The Apache Software Foundation - Apache Derby - 10.16.1.1 - (1901046): instance a816c00e-0193-0744-314b-000001392068 
on database directory D:\UNI\ciber\master\APP\practicas\P1\store-app\work\database with class loader jdk.internal.loader.ClassLoaders$AppClassLoader@76ed5528 
Loaded from file:/C:/Users/Jorge/.m2/repository/org/apache/derby/derby/10.16.1.1/derby-10.16.1.1.jar
java.vendor=Eclipse Adoptium
java.runtime.version=21.0.4+7-LTS
user.dir=D:\UNI\ciber\master\APP\practicas\P1\store-app
os.name=Windows 11
os.arch=amd64
os.version=10.0
derby.system.home=null
Database Class Loader started - derby.database.classpath=''
=======
Thu Nov 07 14:46:15 CET 2024 Thread[#54,Thread-5,5,main] Cleanup action starting
java.sql.SQLException: Database 'work/database' not found.
	at org.apache.derby.impl.jdbc.SQLExceptionFactory.getSQLException(SQLExceptionFactory.java:115)
	at org.apache.derby.impl.jdbc.SQLExceptionFactory.getSQLException(SQLExceptionFactory.java:141)
	at org.apache.derby.impl.jdbc.Util.generateCsSQLException(Util.java:225)
	at org.apache.derby.impl.jdbc.Util.generateCsSQLException(Util.java:220)
	at org.apache.derby.impl.jdbc.EmbedConnection.newSQLException(EmbedConnection.java:3208)
	at org.apache.derby.impl.jdbc.EmbedConnection.handleDBNotFound(EmbedConnection.java:767)
	at org.apache.derby.impl.jdbc.EmbedConnection.<init>(EmbedConnection.java:437)
	at org.apache.derby.iapi.jdbc.InternalDriver.getNewEmbedConnection(InternalDriver.java:630)
	at org.apache.derby.iapi.jdbc.InternalDriver$LoginCallable.call(InternalDriver.java:400)
	at org.apache.derby.iapi.jdbc.InternalDriver$LoginCallable.call(InternalDriver.java:376)
	at java.base/java.util.concurrent.FutureTask.run(FutureTask.java:317)
	at java.base/java.util.concurrent.ThreadPoolExecutor.runWorker(ThreadPoolExecutor.java:1144)
	at java.base/java.util.concurrent.ThreadPoolExecutor$Worker.run(ThreadPoolExecutor.java:642)
	at java.base/java.lang.Thread.run(Thread.java:1575)
Caused by: ERROR XJ004: Database 'work/database' not found.
	at org.apache.derby.shared.common.error.StandardException.newException(StandardException.java:299)
	at org.apache.derby.impl.jdbc.SQLExceptionFactory.wrapArgsForTransportAcrossDRDA(SQLExceptionFactory.java:170)
	at org.apache.derby.impl.jdbc.SQLExceptionFactory.getSQLException(SQLExceptionFactory.java:75)
	... 13 more
============= begin nested exception, level (1) ===========
ERROR XJ004: Database 'work/database' not found.
	at org.apache.derby.shared.common.error.StandardException.newException(StandardException.java:299)
	at org.apache.derby.impl.jdbc.SQLExceptionFactory.wrapArgsForTransportAcrossDRDA(SQLExceptionFactory.java:170)
	at org.apache.derby.impl.jdbc.SQLExceptionFactory.getSQLException(SQLExceptionFactory.java:75)
	at org.apache.derby.impl.jdbc.SQLExceptionFactory.getSQLException(SQLExceptionFactory.java:141)
	at org.apache.derby.impl.jdbc.Util.generateCsSQLException(Util.java:225)
	at org.apache.derby.impl.jdbc.Util.generateCsSQLException(Util.java:220)
	at org.apache.derby.impl.jdbc.EmbedConnection.newSQLException(EmbedConnection.java:3208)
	at org.apache.derby.impl.jdbc.EmbedConnection.handleDBNotFound(EmbedConnection.java:767)
	at org.apache.derby.impl.jdbc.EmbedConnection.<init>(EmbedConnection.java:437)
	at org.apache.derby.iapi.jdbc.InternalDriver.getNewEmbedConnection(InternalDriver.java:630)
	at org.apache.derby.iapi.jdbc.InternalDriver$LoginCallable.call(InternalDriver.java:400)
	at org.apache.derby.iapi.jdbc.InternalDriver$LoginCallable.call(InternalDriver.java:376)
	at java.base/java.util.concurrent.FutureTask.run(FutureTask.java:317)
	at java.base/java.util.concurrent.ThreadPoolExecutor.runWorker(ThreadPoolExecutor.java:1144)
	at java.base/java.util.concurrent.ThreadPoolExecutor$Worker.run(ThreadPoolExecutor.java:642)
	at java.base/java.lang.Thread.run(Thread.java:1575)
============= end nested exception, level (1) ===========
Cleanup action completed
Thu Nov 07 14:46:32 CET 2024 Thread[#551,Thread-9,5,main] Cleanup action starting
java.sql.SQLException: Database 'work/database' not found.
	at org.apache.derby.impl.jdbc.SQLExceptionFactory.getSQLException(SQLExceptionFactory.java:115)
	at org.apache.derby.impl.jdbc.SQLExceptionFactory.getSQLException(SQLExceptionFactory.java:141)
	at org.apache.derby.impl.jdbc.Util.generateCsSQLException(Util.java:225)
	at org.apache.derby.impl.jdbc.Util.generateCsSQLException(Util.java:220)
	at org.apache.derby.impl.jdbc.EmbedConnection.newSQLException(EmbedConnection.java:3208)
	at org.apache.derby.impl.jdbc.EmbedConnection.handleDBNotFound(EmbedConnection.java:767)
	at org.apache.derby.impl.jdbc.EmbedConnection.<init>(EmbedConnection.java:437)
	at org.apache.derby.iapi.jdbc.InternalDriver.getNewEmbedConnection(InternalDriver.java:630)
	at org.apache.derby.iapi.jdbc.InternalDriver$LoginCallable.call(InternalDriver.java:400)
	at org.apache.derby.iapi.jdbc.InternalDriver$LoginCallable.call(InternalDriver.java:376)
	at java.base/java.util.concurrent.FutureTask.run(FutureTask.java:317)
	at java.base/java.util.concurrent.ThreadPoolExecutor.runWorker(ThreadPoolExecutor.java:1144)
	at java.base/java.util.concurrent.ThreadPoolExecutor$Worker.run(ThreadPoolExecutor.java:642)
	at java.base/java.lang.Thread.run(Thread.java:1575)
Caused by: ERROR XJ004: Database 'work/database' not found.
	at org.apache.derby.shared.common.error.StandardException.newException(StandardException.java:299)
	at org.apache.derby.impl.jdbc.SQLExceptionFactory.wrapArgsForTransportAcrossDRDA(SQLExceptionFactory.java:170)
	at org.apache.derby.impl.jdbc.SQLExceptionFactory.getSQLException(SQLExceptionFactory.java:75)
	... 13 more
============= begin nested exception, level (1) ===========
ERROR XJ004: Database 'work/database' not found.
	at org.apache.derby.shared.common.error.StandardException.newException(StandardException.java:299)
	at org.apache.derby.impl.jdbc.SQLExceptionFactory.wrapArgsForTransportAcrossDRDA(SQLExceptionFactory.java:170)
	at org.apache.derby.impl.jdbc.SQLExceptionFactory.getSQLException(SQLExceptionFactory.java:75)
	at org.apache.derby.impl.jdbc.SQLExceptionFactory.getSQLException(SQLExceptionFactory.java:141)
	at org.apache.derby.impl.jdbc.Util.generateCsSQLException(Util.java:225)
	at org.apache.derby.impl.jdbc.Util.generateCsSQLException(Util.java:220)
	at org.apache.derby.impl.jdbc.EmbedConnection.newSQLException(EmbedConnection.java:3208)
	at org.apache.derby.impl.jdbc.EmbedConnection.handleDBNotFound(EmbedConnection.java:767)
	at org.apache.derby.impl.jdbc.EmbedConnection.<init>(EmbedConnection.java:437)
	at org.apache.derby.iapi.jdbc.InternalDriver.getNewEmbedConnection(InternalDriver.java:630)
	at org.apache.derby.iapi.jdbc.InternalDriver$LoginCallable.call(InternalDriver.java:400)
	at org.apache.derby.iapi.jdbc.InternalDriver$LoginCallable.call(InternalDriver.java:376)
	at java.base/java.util.concurrent.FutureTask.run(FutureTask.java:317)
	at java.base/java.util.concurrent.ThreadPoolExecutor.runWorker(ThreadPoolExecutor.java:1144)
	at java.base/java.util.concurrent.ThreadPoolExecutor$Worker.run(ThreadPoolExecutor.java:642)
	at java.base/java.lang.Thread.run(Thread.java:1575)
============= end nested exception, level (1) ===========
Cleanup action completed
Thu Nov 07 14:47:57 CET 2024 Thread[#553,Thread-10,5,main] Cleanup action starting
java.sql.SQLException: Database 'work/database' not found.
	at org.apache.derby.impl.jdbc.SQLExceptionFactory.getSQLException(SQLExceptionFactory.java:115)
	at org.apache.derby.impl.jdbc.SQLExceptionFactory.getSQLException(SQLExceptionFactory.java:141)
	at org.apache.derby.impl.jdbc.Util.generateCsSQLException(Util.java:225)
	at org.apache.derby.impl.jdbc.Util.generateCsSQLException(Util.java:220)
	at org.apache.derby.impl.jdbc.EmbedConnection.newSQLException(EmbedConnection.java:3208)
	at org.apache.derby.impl.jdbc.EmbedConnection.handleDBNotFound(EmbedConnection.java:767)
	at org.apache.derby.impl.jdbc.EmbedConnection.<init>(EmbedConnection.java:437)
	at org.apache.derby.iapi.jdbc.InternalDriver.getNewEmbedConnection(InternalDriver.java:630)
	at org.apache.derby.iapi.jdbc.InternalDriver$LoginCallable.call(InternalDriver.java:400)
	at org.apache.derby.iapi.jdbc.InternalDriver$LoginCallable.call(InternalDriver.java:376)
	at java.base/java.util.concurrent.FutureTask.run(FutureTask.java:317)
	at java.base/java.util.concurrent.ThreadPoolExecutor.runWorker(ThreadPoolExecutor.java:1144)
	at java.base/java.util.concurrent.ThreadPoolExecutor$Worker.run(ThreadPoolExecutor.java:642)
	at java.base/java.lang.Thread.run(Thread.java:1575)
Caused by: ERROR XJ004: Database 'work/database' not found.
	at org.apache.derby.shared.common.error.StandardException.newException(StandardException.java:299)
	at org.apache.derby.impl.jdbc.SQLExceptionFactory.wrapArgsForTransportAcrossDRDA(SQLExceptionFactory.java:170)
	at org.apache.derby.impl.jdbc.SQLExceptionFactory.getSQLException(SQLExceptionFactory.java:75)
	... 13 more
============= begin nested exception, level (1) ===========
ERROR XJ004: Database 'work/database' not found.
	at org.apache.derby.shared.common.error.StandardException.newException(StandardException.java:299)
	at org.apache.derby.impl.jdbc.SQLExceptionFactory.wrapArgsForTransportAcrossDRDA(SQLExceptionFactory.java:170)
	at org.apache.derby.impl.jdbc.SQLExceptionFactory.getSQLException(SQLExceptionFactory.java:75)
	at org.apache.derby.impl.jdbc.SQLExceptionFactory.getSQLException(SQLExceptionFactory.java:141)
	at org.apache.derby.impl.jdbc.Util.generateCsSQLException(Util.java:225)
	at org.apache.derby.impl.jdbc.Util.generateCsSQLException(Util.java:220)
	at org.apache.derby.impl.jdbc.EmbedConnection.newSQLException(EmbedConnection.java:3208)
	at org.apache.derby.impl.jdbc.EmbedConnection.handleDBNotFound(EmbedConnection.java:767)
	at org.apache.derby.impl.jdbc.EmbedConnection.<init>(EmbedConnection.java:437)
	at org.apache.derby.iapi.jdbc.InternalDriver.getNewEmbedConnection(InternalDriver.java:630)
	at org.apache.derby.iapi.jdbc.InternalDriver$LoginCallable.call(InternalDriver.java:400)
	at org.apache.derby.iapi.jdbc.InternalDriver$LoginCallable.call(InternalDriver.java:376)
	at java.base/java.util.concurrent.FutureTask.run(FutureTask.java:317)
	at java.base/java.util.concurrent.ThreadPoolExecutor.runWorker(ThreadPoolExecutor.java:1144)
	at java.base/java.util.concurrent.ThreadPoolExecutor$Worker.run(ThreadPoolExecutor.java:642)
	at java.base/java.lang.Thread.run(Thread.java:1575)
============= end nested exception, level (1) ===========
Cleanup action completed
>>>>>>> 7b01d37 (Arregladas CWE-209 y CWE-20)
